2024-10-05 22:21:55,530 - ERROR - Failed to scrape data: No connection adapters were found for 'date_time                           05 October 2024 - 08:23 PM\ndate                                                2024-10-05\ntime                                                  20:23:00\nlatitude                                                  8.31\nlongitude                                                 8.31\ndepth_km                                                  20.0\nmagnitude                                                  1.9\nlocation          025 km S 77° E of Hinatuan (Surigao Del Sur)\nhlink        https://earthquake.phivolcs.dost.gov.ph/2024_E...\nName: 0, dtype: object'
Traceback (most recent call last):
  File "Z:\Python\PhilippineEarthquakeWebScrapper\main.py", line 175, in scrape_detail_data
    df_data['details'] = df_data.apply(get_details, axis = 1)
                         ^^^^^^^^^^^^^^^^^^^^^^^^^^^^^^^^^^^^
  File "Z:\Python\PhilippineEarthquakeWebScrapper\pheq_env\Lib\site-packages\pandas\core\frame.py", line 10374, in apply
    return op.apply().__finalize__(self, method="apply")
           ^^^^^^^^^^
  File "Z:\Python\PhilippineEarthquakeWebScrapper\pheq_env\Lib\site-packages\pandas\core\apply.py", line 916, in apply
    return self.apply_standard()
           ^^^^^^^^^^^^^^^^^^^^^
  File "Z:\Python\PhilippineEarthquakeWebScrapper\pheq_env\Lib\site-packages\pandas\core\apply.py", line 1063, in apply_standard
    results, res_index = self.apply_series_generator()
                         ^^^^^^^^^^^^^^^^^^^^^^^^^^^^^
  File "Z:\Python\PhilippineEarthquakeWebScrapper\pheq_env\Lib\site-packages\pandas\core\apply.py", line 1081, in apply_series_generator
    results[i] = self.func(v, *self.args, **self.kwargs)
                 ^^^^^^^^^^^^^^^^^^^^^^^^^^^^^^^^^^^^^^^
  File "Z:\Python\PhilippineEarthquakeWebScrapper\main.py", line 157, in get_details
    response = requests.get(link, verify=False)  # 'verify=False' disables SSL certificate check
               ^^^^^^^^^^^^^^^^^^^^^^^^^^^^^^^^
  File "Z:\Python\PhilippineEarthquakeWebScrapper\pheq_env\Lib\site-packages\requests\api.py", line 73, in get
    return request("get", url, params=params, **kwargs)
           ^^^^^^^^^^^^^^^^^^^^^^^^^^^^^^^^^^^^^^^^^^^^
  File "Z:\Python\PhilippineEarthquakeWebScrapper\pheq_env\Lib\site-packages\requests\api.py", line 59, in request
    return session.request(method=method, url=url, **kwargs)
           ^^^^^^^^^^^^^^^^^^^^^^^^^^^^^^^^^^^^^^^^^^^^^^^^^
  File "Z:\Python\PhilippineEarthquakeWebScrapper\pheq_env\Lib\site-packages\requests\sessions.py", line 589, in request
    resp = self.send(prep, **send_kwargs)
           ^^^^^^^^^^^^^^^^^^^^^^^^^^^^^^
  File "Z:\Python\PhilippineEarthquakeWebScrapper\pheq_env\Lib\site-packages\requests\sessions.py", line 697, in send
    adapter = self.get_adapter(url=request.url)
              ^^^^^^^^^^^^^^^^^^^^^^^^^^^^^^^^^
  File "Z:\Python\PhilippineEarthquakeWebScrapper\pheq_env\Lib\site-packages\requests\sessions.py", line 792, in get_adapter
    raise InvalidSchema(f"No connection adapters were found for {url!r}")
requests.exceptions.InvalidSchema: No connection adapters were found for 'date_time                           05 October 2024 - 08:23 PM\ndate                                                2024-10-05\ntime                                                  20:23:00\nlatitude                                                  8.31\nlongitude                                                 8.31\ndepth_km                                                  20.0\nmagnitude                                                  1.9\nlocation          025 km S 77° E of Hinatuan (Surigao Del Sur)\nhlink        https://earthquake.phivolcs.dost.gov.ph/2024_E...\nName: 0, dtype: object'
