2024-10-05 22:22:52,185 - ERROR - Failed to scrape data: scrape_detail_data.<locals>.get_details() got an unexpected keyword argument 'axis'
Traceback (most recent call last):
  File "Z:\Python\PhilippineEarthquakeWebScrapper\main.py", line 175, in scrape_detail_data
    df_data['details'] = df_data['hlink'].apply(get_details, axis = 1)
                         ^^^^^^^^^^^^^^^^^^^^^^^^^^^^^^^^^^^^^^^^^^^^^
  File "Z:\Python\PhilippineEarthquakeWebScrapper\pheq_env\Lib\site-packages\pandas\core\series.py", line 4924, in apply
    ).apply()
      ^^^^^^^
  File "Z:\Python\PhilippineEarthquakeWebScrapper\pheq_env\Lib\site-packages\pandas\core\apply.py", line 1427, in apply
    return self.apply_standard()
           ^^^^^^^^^^^^^^^^^^^^^
  File "Z:\Python\PhilippineEarthquakeWebScrapper\pheq_env\Lib\site-packages\pandas\core\apply.py", line 1507, in apply_standard
    mapped = obj._map_values(
             ^^^^^^^^^^^^^^^^
  File "Z:\Python\PhilippineEarthquakeWebScrapper\pheq_env\Lib\site-packages\pandas\core\base.py", line 921, in _map_values
    return algorithms.map_array(arr, mapper, na_action=na_action, convert=convert)
           ^^^^^^^^^^^^^^^^^^^^^^^^^^^^^^^^^^^^^^^^^^^^^^^^^^^^^^^^^^^^^^^^^^^^^^^
  File "Z:\Python\PhilippineEarthquakeWebScrapper\pheq_env\Lib\site-packages\pandas\core\algorithms.py", line 1743, in map_array
    return lib.map_infer(values, mapper, convert=convert)
           ^^^^^^^^^^^^^^^^^^^^^^^^^^^^^^^^^^^^^^^^^^^^^^
  File "lib.pyx", line 2972, in pandas._libs.lib.map_infer
  File "Z:\Python\PhilippineEarthquakeWebScrapper\pheq_env\Lib\site-packages\pandas\core\apply.py", line 1496, in curried
    return func(x, *self.args, **self.kwargs)
           ^^^^^^^^^^^^^^^^^^^^^^^^^^^^^^^^^^
TypeError: scrape_detail_data.<locals>.get_details() got an unexpected keyword argument 'axis'
